<robot name="my_robot" xmlns:xacro="http://www.ros.org/wiki/xacro">
  <xacro:include filename="$(find my_robot)/urdf/my_robot.gazebo"/>
  <link name="robot_footprint"></link>

  <joint name="robot_footprint_joint" type="fixed">
    <origin xyz="0 0 0" rpy="0 0 0" />
    <parent link="robot_footprint"/>
    <child link="chassis" />
  </joint>

  <joint type="continuous" name="left_wheel_hinge">
    <origin xyz="0 0.15 0" rpy="0 0 0"/>
    <child link="left_wheel"/>
    <parent link="chassis"/>
    <axis xyz="0 1 0" rpy="0 0 0"/>
    <limit effort="10000" velocity="1000"/>
    <dynamics damping="1.0" friction="1.0"/>
  </joint>

  <joint type="continuous" name="right_wheel_hinge">
    <origin xyz="0 -0.15 0" rpy="0 0 0"/>
    <child link="right_wheel"/>
    <parent link="chassis"/>
    <axis xyz="0 1 0" rpy="0 0 0"/>
    <limit effort="10000" velocity="1000"/>
    <dynamics damping="1.0" friction="1.0"/>
  </joint>

  <joint name="camera_joint" type="fixed">
    <origin xyz="0.2 0.0 0.0" rpy="0.0 0.0 0.0"/>
    <parent link="chassis"/>
    <child link="camera"/>
    <axis xyz="0 1 0"/>
    <limit lower="0.0" upper="0.0" effort="0.0" velocity="0.0"/>
  </joint>

  <joint name="hokuyo_joint" type="fixed">
    <origin xyz="0.15 0.0 0.1" rpy="0.0 0.0 0.0"/>
    <parent link="chassis"/>
    <child link="hokuyo"/>
    <axis xyz="0 1 0"/>
    <limit lower="0.0" upper="0.0" effort="0.0" velocity="0.0"/>
  </joint>

  <link name='chassis'>
    <pose>0 0 0.1 0 0 0</pose>

    <inertial>
      <mass value="15.0"/>
      <origin xyz="0.0 0 0" rpy=" 0 0 0"/>
      <inertia
          ixx="0.1" ixy="0" ixz="0"
          iyy="0.1" iyz="0"
          izz="0.1"
      />
    </inertial>

    <collision name='collision'>
      <origin xyz="0 0 0" rpy=" 0 0 0"/> 
      <geometry>
        <box size=".42 .22 .12"/>
      </geometry>
    </collision>

    <visual name='chassis_visual'>
      <origin xyz="0 0 0" rpy=" 0 0 0"/>
      <geometry>
        <box size=".42 .22 .12"/>
      </geometry>
    </visual>


    <collision name='back_caster_collision'>
      <origin xyz="-0.15 0 -0.05" rpy=" 0 0 0"/>
      <geometry>
        <sphere radius="0.06"/>
      </geometry>
    </collision>

    <visual name='back_caster_visual'>
      <origin xyz="-0.15 0 -0.05" rpy=" 0 0 0"/>
      <geometry>
        <sphere radius="0.06"/>
      </geometry>
    </visual>

    <collision name='front_caster_collision'>
      <origin xyz="0.15 0 -0.05" rpy=" 0 0 0"/>
      <geometry>
        <sphere radius="0.06"/>
      </geometry>
    </collision>

    <visual name='front_caster_visual'>
      <origin xyz="0.15 0 -0.05" rpy=" 0 0 0"/>
      <geometry>
        <sphere radius="0.06"/>
      </geometry>
    </visual>

  </link>

  <link name="left_wheel">
    <inertial>
      <origin xyz="0.0 0.0 0.0" rpy="0.0 1.5707 1.5707"/>
      <mass value="5.0"/>
      <inertia ixx="0.1" ixy="0.0" ixz="0.0" iyy="0.1" iyz="0.0" izz="0.1"/>
    </inertial>
    <visual name="">
      <origin xyz="0.0 0.0 0.0" rpy="0.0 1.5707 1.5707"/>
      <geometry>
        <cylinder radius="0.115" length="0.06"/>
      </geometry>
      <material name="">
        <color rgba="1.0 0.0 0.0 1.0"/>
        <texture filename=""/>
      </material>
    </visual>
    <collision>
      <origin xyz="0.0 0.0 0.0" rpy="0.0 1.5707 1.5707"/>
      <geometry>
        <cylinder radius="0.115" length="0.06"/>
      </geometry>
    </collision>
  </link>

  <link name="right_wheel">
    <inertial>
      <origin xyz="0.0 0.0 0.0" rpy="0.0 1.5707 1.5707"/>
      <mass value="5.0"/>
      <inertia ixx="0.1" ixy="0.0" ixz="0.0" iyy="0.1" iyz="0.0" izz="0.1"/>
    </inertial>
    <visual name="">
      <origin xyz="0.0 0.0 0.0" rpy="0.0 1.5707 1.5707"/>
      <geometry>
        <cylinder radius="0.115" length="0.06"/>
      </geometry>
      <material name="">
        <color rgba="1.0 0.0 0.0 1.0"/>
        <texture filename=""/>
      </material>
    </visual>
    <collision>
      <origin xyz="0.0 0.0 0.0" rpy="0.0 1.5707 1.5707"/>
      <geometry>
        <cylinder radius="0.115" length="0.06"/>
      </geometry>
    </collision>
  </link>

  <link name="camera">
    <inertial>
      <origin xyz="0.0 0.0 0.0" rpy="0.0 0.0 0.0"/>
      <mass value="0.1"/>
      <inertia ixx="1e-6" ixy="0.0" ixz="0.0" iyy="1e-6" iyz="0.0" izz="1e-6"/>
    </inertial>
    <visual name="">
      <origin xyz="0.0 0.0 0.0" rpy="0.0 0.0 0.0"/>
      <geometry>
        <box size="0.05 0.05 0.05"/>
      </geometry>
      <material name="">
        <color rgba="1.0 0.0 0.0 1.0"/>
        <texture filename=""/>
      </material>
    </visual>
    <collision>
      <origin xyz="0.0 0.0 0.0" rpy="0.0 0.0 0.0"/>
      <geometry>
        <box size="0.05 0.05 0.05"/>
      </geometry>
    </collision>
  </link>

  <link name="hokuyo">
    <inertial>
      <origin xyz="0.0 0.0 0.0" rpy="0.0 0.0 0.0"/>
      <mass value="1e-5"/>
      <inertia ixx="1e-6" ixy="0.0" ixz="0.0" iyy="1e-6" iyz="0.0" izz="1e-6"/>
    </inertial>
    <collision>
      <origin xyz="0.0 0.0 0.0" rpy="0.0 0.0 0.0"/>
      <geometry>
        <box size="0.1 0.1 0.1"/>
      </geometry>
    </collision>
    <visual name="">
      <origin xyz="0.0 0.0 0.0" rpy="0.0 0.0 0.0"/>
      <geometry>
        <mesh filename="package://my_robot/meshes/hokuyo.dae"/>
      </geometry>
      <material name="">
        <color rgba="0.0 0.0 1.0 0.0"/>
        <texture filename=""/>
      </material>
    </visual>
  </link>

  <gazebo reference="left_wheel">
      <material>Gazebo/Green</material>
  </gazebo>

  <gazebo reference="right_wheel">
      <material>Gazebo/Green</material>
  </gazebo>

  <gazebo reference="chassis">
      <material>Gazebo/Blue</material>
  </gazebo>

  <gazebo reference="camera">
      <material>Gazebo/Yellow</material>
  </gazebo>

</robot>